2024-05-26 13:19:26,137:ERROR:Error in processing data
Traceback (most recent call last):
  File "D:\UWien\NTF\main\Trial.py", line 283, in process_data_thread
    kwargs['eps'] = float(self.eps_entry.get())
                    ^^^^^^^^^^^^^^^^^^^^^^^^^^^
ValueError: could not convert string to float: ''
2024-05-28 15:40:55,753:ERROR:Error in processing data
Traceback (most recent call last):
  File "D:\UWien\NTF\main\NTF_testbuild_v2.0_Final.py", line 234, in process_data_thread
    data = calculate_parameters(data)
           ^^^^^^^^^^^^^^^^^^^^^^^^^^
  File "D:\UWien\NTF\main\NTF_testbuild_v2.0_Final.py", line 27, in calculate_parameters
    data['displacement'] = np.sqrt((data['X'] - data['X'].iloc[0])**2 + (data['Y'] - data['Y'].iloc[0])**2)
                                                ~~~~~~~~~~~~~~^^^
  File "C:\Users\chanu\AppData\Roaming\Python\Python312\site-packages\pandas\core\indexing.py", line 1191, in __getitem__
    return self._getitem_axis(maybe_callable, axis=axis)
           ^^^^^^^^^^^^^^^^^^^^^^^^^^^^^^^^^^^^^^^^^^^^^
  File "C:\Users\chanu\AppData\Roaming\Python\Python312\site-packages\pandas\core\indexing.py", line 1752, in _getitem_axis
    self._validate_integer(key, axis)
  File "C:\Users\chanu\AppData\Roaming\Python\Python312\site-packages\pandas\core\indexing.py", line 1685, in _validate_integer
    raise IndexError("single positional indexer is out-of-bounds")
IndexError: single positional indexer is out-of-bounds
2024-05-28 15:45:00,663:ERROR:Error in processing data
Traceback (most recent call last):
  File "D:\UWien\NTF\main\NTF_testbuild_v2.0_Final.py", line 234, in process_data_thread
    data = calculate_parameters(data)
           ^^^^^^^^^^^^^^^^^^^^^^^^^^
  File "D:\UWien\NTF\main\NTF_testbuild_v2.0_Final.py", line 27, in calculate_parameters
    data['displacement'] = np.sqrt((data['X'] - data['X'].iloc[0])**2 + (data['Y'] - data['Y'].iloc[0])**2)
                                                ~~~~~~~~~~~~~~^^^
  File "C:\Users\chanu\AppData\Roaming\Python\Python312\site-packages\pandas\core\indexing.py", line 1191, in __getitem__
    return self._getitem_axis(maybe_callable, axis=axis)
           ^^^^^^^^^^^^^^^^^^^^^^^^^^^^^^^^^^^^^^^^^^^^^
  File "C:\Users\chanu\AppData\Roaming\Python\Python312\site-packages\pandas\core\indexing.py", line 1752, in _getitem_axis
    self._validate_integer(key, axis)
  File "C:\Users\chanu\AppData\Roaming\Python\Python312\site-packages\pandas\core\indexing.py", line 1685, in _validate_integer
    raise IndexError("single positional indexer is out-of-bounds")
IndexError: single positional indexer is out-of-bounds
